Traceback (most recent call last):
  File "/opt/hostedtoolcache/Python/3.11.8/x64/lib/python3.11/site-packages/jupyter_cache/executors/utils.py", line 58, in single_nb_execution
    executenb(
  File "/opt/hostedtoolcache/Python/3.11.8/x64/lib/python3.11/site-packages/nbclient/client.py", line 1314, in execute
    return NotebookClient(nb=nb, resources=resources, km=km, **kwargs).execute()
           ^^^^^^^^^^^^^^^^^^^^^^^^^^^^^^^^^^^^^^^^^^^^^^^^^^^^^^^^^^^^^^^^^^^^^
  File "/opt/hostedtoolcache/Python/3.11.8/x64/lib/python3.11/site-packages/jupyter_core/utils/__init__.py", line 165, in wrapped
    return loop.run_until_complete(inner)
           ^^^^^^^^^^^^^^^^^^^^^^^^^^^^^^
  File "/opt/hostedtoolcache/Python/3.11.8/x64/lib/python3.11/asyncio/base_events.py", line 654, in run_until_complete
    return future.result()
           ^^^^^^^^^^^^^^^
  File "/opt/hostedtoolcache/Python/3.11.8/x64/lib/python3.11/site-packages/nbclient/client.py", line 709, in async_execute
    await self.async_execute_cell(
  File "/opt/hostedtoolcache/Python/3.11.8/x64/lib/python3.11/site-packages/nbclient/client.py", line 1062, in async_execute_cell
    await self._check_raise_for_error(cell, cell_index, exec_reply)
  File "/opt/hostedtoolcache/Python/3.11.8/x64/lib/python3.11/site-packages/nbclient/client.py", line 918, in _check_raise_for_error
    raise CellExecutionError.from_cell_and_msg(cell, exec_reply_content)
nbclient.exceptions.CellExecutionError: An error occurred while executing the following cell:
------------------
import h3

import geopandas
import geodatasets
import contextily as cx
import matplotlib.pyplot as plt

def plot_df(df, column=None, ax=None):
    'Plot based on the `geometry` column of a GeoPandas dataframe'
    df = df.copy()
    df = df.to_crs(epsg=3857) # web mercator

    if ax is None:
        fig, ax = plt.subplots(figsize=(8,8))
    ax.get_xaxis().set_visible(False)
    ax.get_yaxis().set_visible(False)
    
    df.plot(
        ax=ax,
        alpha=0.5, edgecolor='k',
        column=column, categorical=True,
        legend=True, legend_kwds={'loc': 'upper left'}, 
    )
    cx.add_basemap(ax, crs=df.crs, source=cx.providers.CartoDB.Positron)

def plot_shape(shape, ax=None):
    df = geopandas.GeoDataFrame({'geometry': [shape]}, crs='EPSG:4326')
    plot_df(df, ax=ax)

def plot_cells(cells, ax=None):
    shape = h3.cells_to_h3shape(cells)
    plot_shape(shape, ax=ax)

def plot_shape_and_cells(shape, res=9):
    fig, axs = plt.subplots(1,2, figsize=(10,5), sharex=True, sharey=True)
    plot_shape(shape, ax=axs[0])
    plot_cells(h3.h3shape_to_cells(shape, res), ax=axs[1])
    fig.tight_layout()
------------------


[0;31m---------------------------------------------------------------------------[0m
[0;31mModuleNotFoundError[0m                       Traceback (most recent call last)
Cell [0;32mIn[1], line 3[0m
[1;32m      1[0m [38;5;28;01mimport[39;00m [38;5;21;01mh3[39;00m
[0;32m----> 3[0m [38;5;28;01mimport[39;00m [38;5;21;01mgeopandas[39;00m
[1;32m      4[0m [38;5;28;01mimport[39;00m [38;5;21;01mgeodatasets[39;00m
[1;32m      5[0m [38;5;28;01mimport[39;00m [38;5;21;01mcontextily[39;00m [38;5;28;01mas[39;00m [38;5;21;01mcx[39;00m

[0;31mModuleNotFoundError[0m: No module named 'geopandas'

